{
 "cells": [
  {
   "cell_type": "code",
   "execution_count": 7,
   "metadata": {
    "colab": {
     "base_uri": "https://localhost:8080/",
     "height": 992
    },
    "colab_type": "code",
    "executionInfo": {
     "elapsed": 24002,
     "status": "ok",
     "timestamp": 1554528943726,
     "user": {
      "displayName": "Laurence Moroney",
      "photoUrl": "https://lh3.googleusercontent.com/-RcxktLY-TBk/AAAAAAAAAAI/AAAAAAAAABY/b4V4dTIqmPI/s64/photo.jpg",
      "userId": "06401446828348966425"
     },
     "user_tz": 420
    },
    "id": "pLTlDFwU1Ux_",
    "outputId": "35a170f8-c16f-48b5-a68a-d456338467eb"
   },
   "outputs": [
    {
     "name": "stdout",
     "output_type": "stream",
     "text": [
      "Requirement already satisfied: tensorflowjs in c:\\users\\aravi\\appdata\\roaming\\python\\python37\\site-packages (1.5.2)\n",
      "Requirement already satisfied: tensorflow-hub==0.7.0 in c:\\anaconda\\lib\\site-packages (from tensorflowjs) (0.7.0)\n",
      "Requirement already satisfied: h5py>=2.8.0 in c:\\anaconda\\lib\\site-packages (from tensorflowjs) (2.9.0)\n",
      "Requirement already satisfied: PyInquirer==1.0.3 in c:\\users\\aravi\\appdata\\roaming\\python\\python37\\site-packages (from tensorflowjs) (1.0.3)\n",
      "Requirement already satisfied: numpy>=1.16.4 in c:\\anaconda\\lib\\site-packages (from tensorflowjs) (1.16.4)\n",
      "Requirement already satisfied: six>=1.12.0 in c:\\users\\aravi\\appdata\\roaming\\python\\python37\\site-packages (from tensorflowjs) (1.13.0)\n",
      "Requirement already satisfied: tensorflow-cpu==2.1.0 in c:\\users\\aravi\\appdata\\roaming\\python\\python37\\site-packages (from tensorflowjs) (2.1.0)\n",
      "Requirement already satisfied: gast==0.2.2 in c:\\anaconda\\lib\\site-packages (from tensorflowjs) (0.2.2)\n",
      "Requirement already satisfied: protobuf>=3.4.0 in c:\\anaconda\\lib\\site-packages (from tensorflow-hub==0.7.0->tensorflowjs) (3.11.3)\n",
      "Requirement already satisfied: Pygments>=2.2.0 in c:\\anaconda\\lib\\site-packages (from PyInquirer==1.0.3->tensorflowjs) (2.4.2)\n",
      "Collecting prompt-toolkit==1.0.14 (from PyInquirer==1.0.3->tensorflowjs)\n",
      "  Using cached https://files.pythonhosted.org/packages/ee/3d/b25d35a9f0d381dd1c02d8e04b37c353caaaff4bc32150328eeebe4931f5/prompt_toolkit-1.0.14-py3-none-any.whl\n",
      "Requirement already satisfied: regex>=2016.11.21 in c:\\users\\aravi\\appdata\\roaming\\python\\python37\\site-packages (from PyInquirer==1.0.3->tensorflowjs) (2020.2.20)\n",
      "Requirement already satisfied: keras-applications>=1.0.8 in c:\\anaconda\\lib\\site-packages (from tensorflow-cpu==2.1.0->tensorflowjs) (1.0.8)\n",
      "Requirement already satisfied: wrapt>=1.11.1 in c:\\users\\aravi\\appdata\\roaming\\python\\python37\\site-packages (from tensorflow-cpu==2.1.0->tensorflowjs) (1.11.2)\n",
      "Requirement already satisfied: astor>=0.6.0 in c:\\anaconda\\lib\\site-packages (from tensorflow-cpu==2.1.0->tensorflowjs) (0.8.1)\n",
      "Requirement already satisfied: opt-einsum>=2.3.2 in c:\\anaconda\\lib\\site-packages (from tensorflow-cpu==2.1.0->tensorflowjs) (3.1.0)\n",
      "Requirement already satisfied: keras-preprocessing>=1.1.0 in c:\\anaconda\\lib\\site-packages (from tensorflow-cpu==2.1.0->tensorflowjs) (1.1.0)\n",
      "Requirement already satisfied: termcolor>=1.1.0 in c:\\anaconda\\lib\\site-packages (from tensorflow-cpu==2.1.0->tensorflowjs) (1.1.0)\n",
      "Requirement already satisfied: wheel>=0.26; python_version >= \"3\" in c:\\anaconda\\lib\\site-packages (from tensorflow-cpu==2.1.0->tensorflowjs) (0.33.4)\n",
      "Requirement already satisfied: grpcio>=1.8.6 in c:\\anaconda\\lib\\site-packages (from tensorflow-cpu==2.1.0->tensorflowjs) (1.27.2)\n",
      "Requirement already satisfied: scipy==1.4.1; python_version >= \"3\" in c:\\anaconda\\lib\\site-packages (from tensorflow-cpu==2.1.0->tensorflowjs) (1.4.1)\n",
      "Requirement already satisfied: tensorflow-estimator<2.2.0,>=2.1.0rc0 in c:\\anaconda\\lib\\site-packages (from tensorflow-cpu==2.1.0->tensorflowjs) (2.1.0)\n",
      "Requirement already satisfied: google-pasta>=0.1.6 in c:\\anaconda\\lib\\site-packages (from tensorflow-cpu==2.1.0->tensorflowjs) (0.1.8)\n",
      "Requirement already satisfied: absl-py>=0.7.0 in c:\\anaconda\\lib\\site-packages (from tensorflow-cpu==2.1.0->tensorflowjs) (0.9.0)\n",
      "Requirement already satisfied: tensorboard<2.2.0,>=2.1.0 in c:\\anaconda\\lib\\site-packages (from tensorflow-cpu==2.1.0->tensorflowjs) (2.1.0)\n",
      "Requirement already satisfied: setuptools in c:\\anaconda\\lib\\site-packages (from protobuf>=3.4.0->tensorflow-hub==0.7.0->tensorflowjs) (41.0.1)\n",
      "Requirement already satisfied: wcwidth in c:\\anaconda\\lib\\site-packages (from prompt-toolkit==1.0.14->PyInquirer==1.0.3->tensorflowjs) (0.1.7)\n",
      "Requirement already satisfied: google-auth<2,>=1.6.3 in c:\\anaconda\\lib\\site-packages (from tensorboard<2.2.0,>=2.1.0->tensorflow-cpu==2.1.0->tensorflowjs) (1.11.2)\n",
      "Requirement already satisfied: requests<3,>=2.21.0 in c:\\anaconda\\lib\\site-packages (from tensorboard<2.2.0,>=2.1.0->tensorflow-cpu==2.1.0->tensorflowjs) (2.22.0)\n",
      "Requirement already satisfied: markdown>=2.6.8 in c:\\anaconda\\lib\\site-packages (from tensorboard<2.2.0,>=2.1.0->tensorflow-cpu==2.1.0->tensorflowjs) (3.2.1)\n",
      "Requirement already satisfied: werkzeug>=0.11.15 in c:\\anaconda\\lib\\site-packages (from tensorboard<2.2.0,>=2.1.0->tensorflow-cpu==2.1.0->tensorflowjs) (0.15.4)\n",
      "Requirement already satisfied: google-auth-oauthlib<0.5,>=0.4.1 in c:\\anaconda\\lib\\site-packages (from tensorboard<2.2.0,>=2.1.0->tensorflow-cpu==2.1.0->tensorflowjs) (0.4.1)\n",
      "Requirement already satisfied: rsa<4.1,>=3.1.4 in c:\\anaconda\\lib\\site-packages (from google-auth<2,>=1.6.3->tensorboard<2.2.0,>=2.1.0->tensorflow-cpu==2.1.0->tensorflowjs) (4.0)\n",
      "Requirement already satisfied: pyasn1-modules>=0.2.1 in c:\\anaconda\\lib\\site-packages (from google-auth<2,>=1.6.3->tensorboard<2.2.0,>=2.1.0->tensorflow-cpu==2.1.0->tensorflowjs) (0.2.8)\n",
      "Requirement already satisfied: cachetools<5.0,>=2.0.0 in c:\\anaconda\\lib\\site-packages (from google-auth<2,>=1.6.3->tensorboard<2.2.0,>=2.1.0->tensorflow-cpu==2.1.0->tensorflowjs) (4.0.0)\n",
      "Requirement already satisfied: certifi>=2017.4.17 in c:\\anaconda\\lib\\site-packages (from requests<3,>=2.21.0->tensorboard<2.2.0,>=2.1.0->tensorflow-cpu==2.1.0->tensorflowjs) (2019.6.16)\n",
      "Requirement already satisfied: idna<2.9,>=2.5 in c:\\anaconda\\lib\\site-packages (from requests<3,>=2.21.0->tensorboard<2.2.0,>=2.1.0->tensorflow-cpu==2.1.0->tensorflowjs) (2.8)\n",
      "Requirement already satisfied: chardet<3.1.0,>=3.0.2 in c:\\anaconda\\lib\\site-packages (from requests<3,>=2.21.0->tensorboard<2.2.0,>=2.1.0->tensorflow-cpu==2.1.0->tensorflowjs) (3.0.4)\n",
      "Requirement already satisfied: urllib3!=1.25.0,!=1.25.1,<1.26,>=1.21.1 in c:\\anaconda\\lib\\site-packages (from requests<3,>=2.21.0->tensorboard<2.2.0,>=2.1.0->tensorflow-cpu==2.1.0->tensorflowjs) (1.24.2)\n",
      "Requirement already satisfied: requests-oauthlib>=0.7.0 in c:\\anaconda\\lib\\site-packages (from google-auth-oauthlib<0.5,>=0.4.1->tensorboard<2.2.0,>=2.1.0->tensorflow-cpu==2.1.0->tensorflowjs) (1.3.0)\n",
      "Requirement already satisfied: pyasn1>=0.1.3 in c:\\anaconda\\lib\\site-packages (from rsa<4.1,>=3.1.4->google-auth<2,>=1.6.3->tensorboard<2.2.0,>=2.1.0->tensorflow-cpu==2.1.0->tensorflowjs) (0.4.8)\n",
      "Requirement already satisfied: oauthlib>=3.0.0 in c:\\anaconda\\lib\\site-packages (from requests-oauthlib>=0.7.0->google-auth-oauthlib<0.5,>=0.4.1->tensorboard<2.2.0,>=2.1.0->tensorflow-cpu==2.1.0->tensorflowjs) (3.1.0)\n",
      "Installing collected packages: prompt-toolkit\n",
      "  Found existing installation: prompt-toolkit 2.0.9\n",
      "    Uninstalling prompt-toolkit-2.0.9:\n",
      "      Successfully uninstalled prompt-toolkit-2.0.9\n",
      "Successfully installed prompt-toolkit-1.0.14\n"
     ]
    },
    {
     "name": "stderr",
     "output_type": "stream",
     "text": [
      "ERROR: jupyter-console 6.0.0 has requirement prompt_toolkit<2.1.0,>=2.0.0, but you'll have prompt-toolkit 1.0.14 which is incompatible.\n",
      "ERROR: ipython 7.6.1 has requirement prompt-toolkit<2.1.0,>=2.0.0, but you'll have prompt-toolkit 1.0.14 which is incompatible.\n"
     ]
    }
   ],
   "source": [
    "!pip install tensorflowjs"
   ]
  },
  {
   "cell_type": "code",
   "execution_count": 8,
   "metadata": {
    "colab": {
     "base_uri": "https://localhost:8080/",
     "height": 18235
    },
    "colab_type": "code",
    "executionInfo": {
     "elapsed": 7152,
     "status": "ok",
     "timestamp": 1554528613939,
     "user": {
      "displayName": "Laurence Moroney",
      "photoUrl": "https://lh3.googleusercontent.com/-RcxktLY-TBk/AAAAAAAAAAI/AAAAAAAAABY/b4V4dTIqmPI/s64/photo.jpg",
      "userId": "06401446828348966425"
     },
     "user_tz": 420
    },
    "id": "vNHv1d2K0Wxg",
    "outputId": "109c8bc7-6d51-4f0a-d3a6-f2943221ff49"
   },
   "outputs": [
    {
     "name": "stderr",
     "output_type": "stream",
     "text": [
      "ERROR:root:Internal Python error in the inspect module.\n",
      "Below is the traceback from this internal error.\n",
      "\n"
     ]
    },
    {
     "name": "stdout",
     "output_type": "stream",
     "text": [
      "Traceback (most recent call last):\n",
      "  File \"C:\\Anaconda\\lib\\site-packages\\IPython\\core\\interactiveshell.py\", line 3325, in run_code\n",
      "    exec(code_obj, self.user_global_ns, self.user_ns)\n",
      "  File \"<ipython-input-8-ca0463f93d77>\", line 4, in <module>\n",
      "    print('\\u2022 Using TensorFlow Version:', tf.__version__)\n",
      "AttributeError: module 'tensorflow' has no attribute '__version__'\n",
      "\n",
      "During handling of the above exception, another exception occurred:\n",
      "\n",
      "Traceback (most recent call last):\n",
      "  File \"C:\\Anaconda\\lib\\site-packages\\IPython\\core\\interactiveshell.py\", line 2039, in showtraceback\n",
      "    stb = value._render_traceback_()\n",
      "AttributeError: 'AttributeError' object has no attribute '_render_traceback_'\n",
      "\n",
      "During handling of the above exception, another exception occurred:\n",
      "\n",
      "Traceback (most recent call last):\n",
      "  File \"C:\\Users\\aravi\\AppData\\Roaming\\Python\\Python37\\site-packages\\tensorflow_core\\python\\pywrap_tensorflow.py\", line 58, in <module>\n",
      "    from tensorflow.python.pywrap_tensorflow_internal import *\n",
      "  File \"C:\\Users\\aravi\\AppData\\Roaming\\Python\\Python37\\site-packages\\tensorflow_core\\python\\pywrap_tensorflow_internal.py\", line 28, in <module>\n",
      "    _pywrap_tensorflow_internal = swig_import_helper()\n",
      "  File \"C:\\Users\\aravi\\AppData\\Roaming\\Python\\Python37\\site-packages\\tensorflow_core\\python\\pywrap_tensorflow_internal.py\", line 24, in swig_import_helper\n",
      "    _mod = imp.load_module('_pywrap_tensorflow_internal', fp, pathname, description)\n",
      "  File \"C:\\Anaconda\\lib\\imp.py\", line 242, in load_module\n",
      "    return load_dynamic(name, filename, file)\n",
      "  File \"C:\\Anaconda\\lib\\imp.py\", line 342, in load_dynamic\n",
      "    return _load(spec)\n",
      "ImportError: DLL load failed: The specified module could not be found.\n",
      "\n",
      "During handling of the above exception, another exception occurred:\n",
      "\n",
      "Traceback (most recent call last):\n",
      "  File \"C:\\Anaconda\\lib\\site-packages\\IPython\\core\\ultratb.py\", line 1101, in get_records\n",
      "    return _fixed_getinnerframes(etb, number_of_lines_of_context, tb_offset)\n",
      "  File \"C:\\Anaconda\\lib\\site-packages\\IPython\\core\\ultratb.py\", line 319, in wrapped\n",
      "    return f(*args, **kwargs)\n",
      "  File \"C:\\Anaconda\\lib\\site-packages\\IPython\\core\\ultratb.py\", line 353, in _fixed_getinnerframes\n",
      "    records = fix_frame_records_filenames(inspect.getinnerframes(etb, context))\n",
      "  File \"C:\\Anaconda\\lib\\inspect.py\", line 1502, in getinnerframes\n",
      "    frameinfo = (tb.tb_frame,) + getframeinfo(tb, context)\n",
      "  File \"C:\\Anaconda\\lib\\inspect.py\", line 1460, in getframeinfo\n",
      "    filename = getsourcefile(frame) or getfile(frame)\n",
      "  File \"C:\\Anaconda\\lib\\inspect.py\", line 696, in getsourcefile\n",
      "    if getattr(getmodule(object, filename), '__loader__', None) is not None:\n",
      "  File \"C:\\Anaconda\\lib\\inspect.py\", line 733, in getmodule\n",
      "    if ismodule(module) and hasattr(module, '__file__'):\n",
      "  File \"C:\\Users\\aravi\\AppData\\Roaming\\Python\\Python37\\site-packages\\tensorflow\\__init__.py\", line 50, in __getattr__\n",
      "    module = self._load()\n",
      "  File \"C:\\Users\\aravi\\AppData\\Roaming\\Python\\Python37\\site-packages\\tensorflow\\__init__.py\", line 44, in _load\n",
      "    module = _importlib.import_module(self.__name__)\n",
      "  File \"C:\\Anaconda\\lib\\importlib\\__init__.py\", line 127, in import_module\n",
      "    return _bootstrap._gcd_import(name[level:], package, level)\n",
      "  File \"<frozen importlib._bootstrap>\", line 1006, in _gcd_import\n",
      "  File \"<frozen importlib._bootstrap>\", line 983, in _find_and_load\n",
      "  File \"<frozen importlib._bootstrap>\", line 953, in _find_and_load_unlocked\n",
      "  File \"<frozen importlib._bootstrap>\", line 219, in _call_with_frames_removed\n",
      "  File \"<frozen importlib._bootstrap>\", line 1006, in _gcd_import\n",
      "  File \"<frozen importlib._bootstrap>\", line 983, in _find_and_load\n",
      "  File \"<frozen importlib._bootstrap>\", line 967, in _find_and_load_unlocked\n",
      "  File \"<frozen importlib._bootstrap>\", line 677, in _load_unlocked\n",
      "  File \"<frozen importlib._bootstrap_external>\", line 728, in exec_module\n",
      "  File \"<frozen importlib._bootstrap>\", line 219, in _call_with_frames_removed\n",
      "  File \"C:\\Users\\aravi\\AppData\\Roaming\\Python\\Python37\\site-packages\\tensorflow_core\\__init__.py\", line 42, in <module>\n",
      "    from . _api.v2 import audio\n",
      "  File \"C:\\Users\\aravi\\AppData\\Roaming\\Python\\Python37\\site-packages\\tensorflow_core\\_api\\v2\\audio\\__init__.py\", line 10, in <module>\n",
      "    from tensorflow.python.ops.gen_audio_ops import decode_wav\n",
      "  File \"C:\\Users\\aravi\\AppData\\Roaming\\Python\\Python37\\site-packages\\tensorflow_core\\python\\ops\\gen_audio_ops.py\", line 8, in <module>\n",
      "    from tensorflow.python import pywrap_tensorflow as _pywrap_tensorflow\n",
      "  File \"C:\\Users\\aravi\\AppData\\Roaming\\Python\\Python37\\site-packages\\tensorflow\\__init__.py\", line 50, in __getattr__\n",
      "    module = self._load()\n",
      "  File \"C:\\Users\\aravi\\AppData\\Roaming\\Python\\Python37\\site-packages\\tensorflow\\__init__.py\", line 44, in _load\n",
      "    module = _importlib.import_module(self.__name__)\n",
      "  File \"C:\\Anaconda\\lib\\importlib\\__init__.py\", line 127, in import_module\n",
      "    return _bootstrap._gcd_import(name[level:], package, level)\n",
      "  File \"C:\\Users\\aravi\\AppData\\Roaming\\Python\\Python37\\site-packages\\tensorflow_core\\python\\__init__.py\", line 49, in <module>\n",
      "    from tensorflow.python import pywrap_tensorflow\n",
      "  File \"C:\\Users\\aravi\\AppData\\Roaming\\Python\\Python37\\site-packages\\tensorflow_core\\python\\pywrap_tensorflow.py\", line 74, in <module>\n",
      "    raise ImportError(msg)\n",
      "ImportError: Traceback (most recent call last):\n",
      "  File \"C:\\Anaconda\\lib\\site-packages\\IPython\\core\\interactiveshell.py\", line 3325, in run_code\n",
      "    exec(code_obj, self.user_global_ns, self.user_ns)\n",
      "  File \"<ipython-input-8-ca0463f93d77>\", line 4, in <module>\n",
      "    print('\\u2022 Using TensorFlow Version:', tf.__version__)\n",
      "AttributeError: module 'tensorflow' has no attribute '__version__'\n",
      "\n",
      "During handling of the above exception, another exception occurred:\n",
      "\n",
      "Traceback (most recent call last):\n",
      "  File \"C:\\Anaconda\\lib\\site-packages\\IPython\\core\\interactiveshell.py\", line 2039, in showtraceback\n",
      "    stb = value._render_traceback_()\n",
      "AttributeError: 'AttributeError' object has no attribute '_render_traceback_'\n",
      "\n",
      "During handling of the above exception, another exception occurred:\n",
      "\n",
      "Traceback (most recent call last):\n",
      "  File \"C:\\Users\\aravi\\AppData\\Roaming\\Python\\Python37\\site-packages\\tensorflow_core\\python\\pywrap_tensorflow.py\", line 58, in <module>\n",
      "    from tensorflow.python.pywrap_tensorflow_internal import *\n",
      "  File \"C:\\Users\\aravi\\AppData\\Roaming\\Python\\Python37\\site-packages\\tensorflow_core\\python\\pywrap_tensorflow_internal.py\", line 28, in <module>\n",
      "    _pywrap_tensorflow_internal = swig_import_helper()\n",
      "  File \"C:\\Users\\aravi\\AppData\\Roaming\\Python\\Python37\\site-packages\\tensorflow_core\\python\\pywrap_tensorflow_internal.py\", line 24, in swig_import_helper\n",
      "    _mod = imp.load_module('_pywrap_tensorflow_internal', fp, pathname, description)\n",
      "  File \"C:\\Anaconda\\lib\\imp.py\", line 242, in load_module\n",
      "    return load_dynamic(name, filename, file)\n",
      "  File \"C:\\Anaconda\\lib\\imp.py\", line 342, in load_dynamic\n",
      "    return _load(spec)\n",
      "ImportError: DLL load failed: The specified module could not be found.\n",
      "\n",
      "\n",
      "Failed to load the native TensorFlow runtime.\n",
      "\n",
      "See https://www.tensorflow.org/install/errors\n",
      "\n",
      "for some common reasons and solutions.  Include the entire stack trace\n",
      "above this error message when asking for help.\n"
     ]
    },
    {
     "ename": "AttributeError",
     "evalue": "module 'tensorflow' has no attribute '__version__'",
     "output_type": "error",
     "traceback": [
      "\u001b[1;31m---------------------------------------------------------------------------\u001b[0m"
     ]
    }
   ],
   "source": [
    "import numpy as np\n",
    "import tensorflow as tf\n",
    "\n",
    "print('\\u2022 Using TensorFlow Version:', tf.__version__)"
   ]
  },
  {
   "cell_type": "code",
   "execution_count": 2,
   "metadata": {},
   "outputs": [
    {
     "name": "stderr",
     "output_type": "stream",
     "text": [
      "ERROR:root:Internal Python error in the inspect module.\n",
      "Below is the traceback from this internal error.\n",
      "\n"
     ]
    },
    {
     "name": "stdout",
     "output_type": "stream",
     "text": [
      "Traceback (most recent call last):\n",
      "  File \"C:\\Anaconda\\lib\\site-packages\\IPython\\core\\interactiveshell.py\", line 3325, in run_code\n",
      "    exec(code_obj, self.user_global_ns, self.user_ns)\n",
      "  File \"<ipython-input-2-ebbf01945128>\", line 1, in <module>\n",
      "    model = tf.keras.models.Sequential([\n",
      "NameError: name 'tf' is not defined\n",
      "\n",
      "During handling of the above exception, another exception occurred:\n",
      "\n",
      "Traceback (most recent call last):\n",
      "  File \"C:\\Anaconda\\lib\\site-packages\\IPython\\core\\interactiveshell.py\", line 2039, in showtraceback\n",
      "    stb = value._render_traceback_()\n",
      "AttributeError: 'NameError' object has no attribute '_render_traceback_'\n",
      "\n",
      "During handling of the above exception, another exception occurred:\n",
      "\n",
      "Traceback (most recent call last):\n",
      "  File \"C:\\Users\\aravi\\AppData\\Roaming\\Python\\Python37\\site-packages\\tensorflow_core\\python\\pywrap_tensorflow.py\", line 58, in <module>\n",
      "    from tensorflow.python.pywrap_tensorflow_internal import *\n",
      "  File \"C:\\Users\\aravi\\AppData\\Roaming\\Python\\Python37\\site-packages\\tensorflow_core\\python\\pywrap_tensorflow_internal.py\", line 28, in <module>\n",
      "    _pywrap_tensorflow_internal = swig_import_helper()\n",
      "  File \"C:\\Users\\aravi\\AppData\\Roaming\\Python\\Python37\\site-packages\\tensorflow_core\\python\\pywrap_tensorflow_internal.py\", line 24, in swig_import_helper\n",
      "    _mod = imp.load_module('_pywrap_tensorflow_internal', fp, pathname, description)\n",
      "  File \"C:\\Anaconda\\lib\\imp.py\", line 242, in load_module\n",
      "    return load_dynamic(name, filename, file)\n",
      "  File \"C:\\Anaconda\\lib\\imp.py\", line 342, in load_dynamic\n",
      "    return _load(spec)\n",
      "ImportError: DLL load failed: The specified module could not be found.\n",
      "\n",
      "During handling of the above exception, another exception occurred:\n",
      "\n",
      "Traceback (most recent call last):\n",
      "  File \"C:\\Anaconda\\lib\\site-packages\\IPython\\core\\ultratb.py\", line 1101, in get_records\n",
      "    return _fixed_getinnerframes(etb, number_of_lines_of_context, tb_offset)\n",
      "  File \"C:\\Anaconda\\lib\\site-packages\\IPython\\core\\ultratb.py\", line 319, in wrapped\n",
      "    return f(*args, **kwargs)\n",
      "  File \"C:\\Anaconda\\lib\\site-packages\\IPython\\core\\ultratb.py\", line 353, in _fixed_getinnerframes\n",
      "    records = fix_frame_records_filenames(inspect.getinnerframes(etb, context))\n",
      "  File \"C:\\Anaconda\\lib\\inspect.py\", line 1502, in getinnerframes\n",
      "    frameinfo = (tb.tb_frame,) + getframeinfo(tb, context)\n",
      "  File \"C:\\Anaconda\\lib\\inspect.py\", line 1460, in getframeinfo\n",
      "    filename = getsourcefile(frame) or getfile(frame)\n",
      "  File \"C:\\Anaconda\\lib\\inspect.py\", line 696, in getsourcefile\n",
      "    if getattr(getmodule(object, filename), '__loader__', None) is not None:\n",
      "  File \"C:\\Anaconda\\lib\\inspect.py\", line 733, in getmodule\n",
      "    if ismodule(module) and hasattr(module, '__file__'):\n",
      "  File \"C:\\Users\\aravi\\AppData\\Roaming\\Python\\Python37\\site-packages\\tensorflow\\__init__.py\", line 50, in __getattr__\n",
      "    module = self._load()\n",
      "  File \"C:\\Users\\aravi\\AppData\\Roaming\\Python\\Python37\\site-packages\\tensorflow\\__init__.py\", line 44, in _load\n",
      "    module = _importlib.import_module(self.__name__)\n",
      "  File \"C:\\Anaconda\\lib\\importlib\\__init__.py\", line 127, in import_module\n",
      "    return _bootstrap._gcd_import(name[level:], package, level)\n",
      "  File \"<frozen importlib._bootstrap>\", line 1006, in _gcd_import\n",
      "  File \"<frozen importlib._bootstrap>\", line 983, in _find_and_load\n",
      "  File \"<frozen importlib._bootstrap>\", line 953, in _find_and_load_unlocked\n",
      "  File \"<frozen importlib._bootstrap>\", line 219, in _call_with_frames_removed\n",
      "  File \"<frozen importlib._bootstrap>\", line 1006, in _gcd_import\n",
      "  File \"<frozen importlib._bootstrap>\", line 983, in _find_and_load\n",
      "  File \"<frozen importlib._bootstrap>\", line 967, in _find_and_load_unlocked\n",
      "  File \"<frozen importlib._bootstrap>\", line 677, in _load_unlocked\n",
      "  File \"<frozen importlib._bootstrap_external>\", line 728, in exec_module\n",
      "  File \"<frozen importlib._bootstrap>\", line 219, in _call_with_frames_removed\n",
      "  File \"C:\\Users\\aravi\\AppData\\Roaming\\Python\\Python37\\site-packages\\tensorflow_core\\__init__.py\", line 42, in <module>\n",
      "    from . _api.v2 import audio\n",
      "  File \"C:\\Users\\aravi\\AppData\\Roaming\\Python\\Python37\\site-packages\\tensorflow_core\\_api\\v2\\audio\\__init__.py\", line 10, in <module>\n",
      "    from tensorflow.python.ops.gen_audio_ops import decode_wav\n",
      "  File \"C:\\Users\\aravi\\AppData\\Roaming\\Python\\Python37\\site-packages\\tensorflow_core\\python\\ops\\gen_audio_ops.py\", line 8, in <module>\n",
      "    from tensorflow.python import pywrap_tensorflow as _pywrap_tensorflow\n",
      "  File \"C:\\Users\\aravi\\AppData\\Roaming\\Python\\Python37\\site-packages\\tensorflow\\__init__.py\", line 50, in __getattr__\n",
      "    module = self._load()\n",
      "  File \"C:\\Users\\aravi\\AppData\\Roaming\\Python\\Python37\\site-packages\\tensorflow\\__init__.py\", line 44, in _load\n",
      "    module = _importlib.import_module(self.__name__)\n",
      "  File \"C:\\Anaconda\\lib\\importlib\\__init__.py\", line 127, in import_module\n",
      "    return _bootstrap._gcd_import(name[level:], package, level)\n",
      "  File \"C:\\Users\\aravi\\AppData\\Roaming\\Python\\Python37\\site-packages\\tensorflow_core\\python\\__init__.py\", line 49, in <module>\n",
      "    from tensorflow.python import pywrap_tensorflow\n",
      "  File \"C:\\Users\\aravi\\AppData\\Roaming\\Python\\Python37\\site-packages\\tensorflow_core\\python\\pywrap_tensorflow.py\", line 74, in <module>\n",
      "    raise ImportError(msg)\n",
      "ImportError: Traceback (most recent call last):\n",
      "  File \"C:\\Anaconda\\lib\\site-packages\\IPython\\core\\interactiveshell.py\", line 3325, in run_code\n",
      "    exec(code_obj, self.user_global_ns, self.user_ns)\n",
      "  File \"<ipython-input-2-ebbf01945128>\", line 1, in <module>\n",
      "    model = tf.keras.models.Sequential([\n",
      "NameError: name 'tf' is not defined\n",
      "\n",
      "During handling of the above exception, another exception occurred:\n",
      "\n",
      "Traceback (most recent call last):\n",
      "  File \"C:\\Anaconda\\lib\\site-packages\\IPython\\core\\interactiveshell.py\", line 2039, in showtraceback\n",
      "    stb = value._render_traceback_()\n",
      "AttributeError: 'NameError' object has no attribute '_render_traceback_'\n",
      "\n",
      "During handling of the above exception, another exception occurred:\n",
      "\n",
      "Traceback (most recent call last):\n",
      "  File \"C:\\Users\\aravi\\AppData\\Roaming\\Python\\Python37\\site-packages\\tensorflow_core\\python\\pywrap_tensorflow.py\", line 58, in <module>\n",
      "    from tensorflow.python.pywrap_tensorflow_internal import *\n",
      "  File \"C:\\Users\\aravi\\AppData\\Roaming\\Python\\Python37\\site-packages\\tensorflow_core\\python\\pywrap_tensorflow_internal.py\", line 28, in <module>\n",
      "    _pywrap_tensorflow_internal = swig_import_helper()\n",
      "  File \"C:\\Users\\aravi\\AppData\\Roaming\\Python\\Python37\\site-packages\\tensorflow_core\\python\\pywrap_tensorflow_internal.py\", line 24, in swig_import_helper\n",
      "    _mod = imp.load_module('_pywrap_tensorflow_internal', fp, pathname, description)\n",
      "  File \"C:\\Anaconda\\lib\\imp.py\", line 242, in load_module\n",
      "    return load_dynamic(name, filename, file)\n",
      "  File \"C:\\Anaconda\\lib\\imp.py\", line 342, in load_dynamic\n",
      "    return _load(spec)\n",
      "ImportError: DLL load failed: The specified module could not be found.\n",
      "\n",
      "\n",
      "Failed to load the native TensorFlow runtime.\n",
      "\n",
      "See https://www.tensorflow.org/install/errors\n",
      "\n",
      "for some common reasons and solutions.  Include the entire stack trace\n",
      "above this error message when asking for help.\n"
     ]
    },
    {
     "ename": "NameError",
     "evalue": "name 'tf' is not defined",
     "output_type": "error",
     "traceback": [
      "\u001b[1;31m---------------------------------------------------------------------------\u001b[0m"
     ]
    }
   ],
   "source": [
    "model = tf.keras.models.Sequential([\n",
    "        tf.keras.layers.Dense(units=1, input_shape=[1])  \n",
    "])\n",
    "\n",
    "model.compile(optimizer='sgd', loss='mean_squared_error')\n",
    "\n",
    "xs = np.array([-1.0,  0.0, 1.0, 2.0, 3.0, 4.0], dtype=float)\n",
    "ys = np.array([-3.0, -1.0, 1.0, 3.0, 5.0, 7.0], dtype=float)\n",
    "\n",
    "model.fit(xs, ys, epochs=500)"
   ]
  },
  {
   "cell_type": "code",
   "execution_count": 3,
   "metadata": {
    "colab": {
     "base_uri": "https://localhost:8080/",
     "height": 35
    },
    "colab_type": "code",
    "executionInfo": {
     "elapsed": 592,
     "status": "ok",
     "timestamp": 1554528625827,
     "user": {
      "displayName": "Laurence Moroney",
      "photoUrl": "https://lh3.googleusercontent.com/-RcxktLY-TBk/AAAAAAAAAAI/AAAAAAAAABY/b4V4dTIqmPI/s64/photo.jpg",
      "userId": "06401446828348966425"
     },
     "user_tz": 420
    },
    "id": "AxSZ4DzJGEKy",
    "outputId": "00023ac5-58cb-4e09-9ac0-9ae8ae59f846"
   },
   "outputs": [
    {
     "name": "stderr",
     "output_type": "stream",
     "text": [
      "ERROR:root:Internal Python error in the inspect module.\n",
      "Below is the traceback from this internal error.\n",
      "\n"
     ]
    },
    {
     "name": "stdout",
     "output_type": "stream",
     "text": [
      "Traceback (most recent call last):\n",
      "  File \"C:\\Anaconda\\lib\\site-packages\\IPython\\core\\interactiveshell.py\", line 3325, in run_code\n",
      "    exec(code_obj, self.user_global_ns, self.user_ns)\n",
      "  File \"<ipython-input-3-5458a4003a80>\", line 1, in <module>\n",
      "    print(model.predict([10.0]))\n",
      "NameError: name 'model' is not defined\n",
      "\n",
      "During handling of the above exception, another exception occurred:\n",
      "\n",
      "Traceback (most recent call last):\n",
      "  File \"C:\\Anaconda\\lib\\site-packages\\IPython\\core\\interactiveshell.py\", line 2039, in showtraceback\n",
      "    stb = value._render_traceback_()\n",
      "AttributeError: 'NameError' object has no attribute '_render_traceback_'\n",
      "\n",
      "During handling of the above exception, another exception occurred:\n",
      "\n",
      "Traceback (most recent call last):\n",
      "  File \"C:\\Users\\aravi\\AppData\\Roaming\\Python\\Python37\\site-packages\\tensorflow_core\\python\\pywrap_tensorflow.py\", line 58, in <module>\n",
      "    from tensorflow.python.pywrap_tensorflow_internal import *\n",
      "  File \"C:\\Users\\aravi\\AppData\\Roaming\\Python\\Python37\\site-packages\\tensorflow_core\\python\\pywrap_tensorflow_internal.py\", line 28, in <module>\n",
      "    _pywrap_tensorflow_internal = swig_import_helper()\n",
      "  File \"C:\\Users\\aravi\\AppData\\Roaming\\Python\\Python37\\site-packages\\tensorflow_core\\python\\pywrap_tensorflow_internal.py\", line 24, in swig_import_helper\n",
      "    _mod = imp.load_module('_pywrap_tensorflow_internal', fp, pathname, description)\n",
      "  File \"C:\\Anaconda\\lib\\imp.py\", line 242, in load_module\n",
      "    return load_dynamic(name, filename, file)\n",
      "  File \"C:\\Anaconda\\lib\\imp.py\", line 342, in load_dynamic\n",
      "    return _load(spec)\n",
      "ImportError: DLL load failed: The specified module could not be found.\n",
      "\n",
      "During handling of the above exception, another exception occurred:\n",
      "\n",
      "Traceback (most recent call last):\n",
      "  File \"C:\\Anaconda\\lib\\site-packages\\IPython\\core\\ultratb.py\", line 1101, in get_records\n",
      "    return _fixed_getinnerframes(etb, number_of_lines_of_context, tb_offset)\n",
      "  File \"C:\\Anaconda\\lib\\site-packages\\IPython\\core\\ultratb.py\", line 319, in wrapped\n",
      "    return f(*args, **kwargs)\n",
      "  File \"C:\\Anaconda\\lib\\site-packages\\IPython\\core\\ultratb.py\", line 353, in _fixed_getinnerframes\n",
      "    records = fix_frame_records_filenames(inspect.getinnerframes(etb, context))\n",
      "  File \"C:\\Anaconda\\lib\\inspect.py\", line 1502, in getinnerframes\n",
      "    frameinfo = (tb.tb_frame,) + getframeinfo(tb, context)\n",
      "  File \"C:\\Anaconda\\lib\\inspect.py\", line 1460, in getframeinfo\n",
      "    filename = getsourcefile(frame) or getfile(frame)\n",
      "  File \"C:\\Anaconda\\lib\\inspect.py\", line 696, in getsourcefile\n",
      "    if getattr(getmodule(object, filename), '__loader__', None) is not None:\n",
      "  File \"C:\\Anaconda\\lib\\inspect.py\", line 733, in getmodule\n",
      "    if ismodule(module) and hasattr(module, '__file__'):\n",
      "  File \"C:\\Users\\aravi\\AppData\\Roaming\\Python\\Python37\\site-packages\\tensorflow\\__init__.py\", line 50, in __getattr__\n",
      "    module = self._load()\n",
      "  File \"C:\\Users\\aravi\\AppData\\Roaming\\Python\\Python37\\site-packages\\tensorflow\\__init__.py\", line 44, in _load\n",
      "    module = _importlib.import_module(self.__name__)\n",
      "  File \"C:\\Anaconda\\lib\\importlib\\__init__.py\", line 127, in import_module\n",
      "    return _bootstrap._gcd_import(name[level:], package, level)\n",
      "  File \"<frozen importlib._bootstrap>\", line 1006, in _gcd_import\n",
      "  File \"<frozen importlib._bootstrap>\", line 983, in _find_and_load\n",
      "  File \"<frozen importlib._bootstrap>\", line 953, in _find_and_load_unlocked\n",
      "  File \"<frozen importlib._bootstrap>\", line 219, in _call_with_frames_removed\n",
      "  File \"<frozen importlib._bootstrap>\", line 1006, in _gcd_import\n",
      "  File \"<frozen importlib._bootstrap>\", line 983, in _find_and_load\n",
      "  File \"<frozen importlib._bootstrap>\", line 967, in _find_and_load_unlocked\n",
      "  File \"<frozen importlib._bootstrap>\", line 677, in _load_unlocked\n",
      "  File \"<frozen importlib._bootstrap_external>\", line 728, in exec_module\n",
      "  File \"<frozen importlib._bootstrap>\", line 219, in _call_with_frames_removed\n",
      "  File \"C:\\Users\\aravi\\AppData\\Roaming\\Python\\Python37\\site-packages\\tensorflow_core\\__init__.py\", line 42, in <module>\n",
      "    from . _api.v2 import audio\n",
      "  File \"C:\\Users\\aravi\\AppData\\Roaming\\Python\\Python37\\site-packages\\tensorflow_core\\_api\\v2\\audio\\__init__.py\", line 10, in <module>\n",
      "    from tensorflow.python.ops.gen_audio_ops import decode_wav\n",
      "  File \"C:\\Users\\aravi\\AppData\\Roaming\\Python\\Python37\\site-packages\\tensorflow_core\\python\\ops\\gen_audio_ops.py\", line 8, in <module>\n",
      "    from tensorflow.python import pywrap_tensorflow as _pywrap_tensorflow\n",
      "  File \"C:\\Users\\aravi\\AppData\\Roaming\\Python\\Python37\\site-packages\\tensorflow\\__init__.py\", line 50, in __getattr__\n",
      "    module = self._load()\n",
      "  File \"C:\\Users\\aravi\\AppData\\Roaming\\Python\\Python37\\site-packages\\tensorflow\\__init__.py\", line 44, in _load\n",
      "    module = _importlib.import_module(self.__name__)\n",
      "  File \"C:\\Anaconda\\lib\\importlib\\__init__.py\", line 127, in import_module\n",
      "    return _bootstrap._gcd_import(name[level:], package, level)\n",
      "  File \"C:\\Users\\aravi\\AppData\\Roaming\\Python\\Python37\\site-packages\\tensorflow_core\\python\\__init__.py\", line 49, in <module>\n",
      "    from tensorflow.python import pywrap_tensorflow\n",
      "  File \"C:\\Users\\aravi\\AppData\\Roaming\\Python\\Python37\\site-packages\\tensorflow_core\\python\\pywrap_tensorflow.py\", line 74, in <module>\n",
      "    raise ImportError(msg)\n",
      "ImportError: Traceback (most recent call last):\n",
      "  File \"C:\\Anaconda\\lib\\site-packages\\IPython\\core\\interactiveshell.py\", line 3325, in run_code\n",
      "    exec(code_obj, self.user_global_ns, self.user_ns)\n",
      "  File \"<ipython-input-3-5458a4003a80>\", line 1, in <module>\n",
      "    print(model.predict([10.0]))\n",
      "NameError: name 'model' is not defined\n",
      "\n",
      "During handling of the above exception, another exception occurred:\n",
      "\n",
      "Traceback (most recent call last):\n",
      "  File \"C:\\Anaconda\\lib\\site-packages\\IPython\\core\\interactiveshell.py\", line 2039, in showtraceback\n",
      "    stb = value._render_traceback_()\n",
      "AttributeError: 'NameError' object has no attribute '_render_traceback_'\n",
      "\n",
      "During handling of the above exception, another exception occurred:\n",
      "\n",
      "Traceback (most recent call last):\n",
      "  File \"C:\\Users\\aravi\\AppData\\Roaming\\Python\\Python37\\site-packages\\tensorflow_core\\python\\pywrap_tensorflow.py\", line 58, in <module>\n",
      "    from tensorflow.python.pywrap_tensorflow_internal import *\n",
      "  File \"C:\\Users\\aravi\\AppData\\Roaming\\Python\\Python37\\site-packages\\tensorflow_core\\python\\pywrap_tensorflow_internal.py\", line 28, in <module>\n",
      "    _pywrap_tensorflow_internal = swig_import_helper()\n",
      "  File \"C:\\Users\\aravi\\AppData\\Roaming\\Python\\Python37\\site-packages\\tensorflow_core\\python\\pywrap_tensorflow_internal.py\", line 24, in swig_import_helper\n",
      "    _mod = imp.load_module('_pywrap_tensorflow_internal', fp, pathname, description)\n",
      "  File \"C:\\Anaconda\\lib\\imp.py\", line 242, in load_module\n",
      "    return load_dynamic(name, filename, file)\n",
      "  File \"C:\\Anaconda\\lib\\imp.py\", line 342, in load_dynamic\n",
      "    return _load(spec)\n",
      "ImportError: DLL load failed: The specified module could not be found.\n",
      "\n",
      "\n",
      "Failed to load the native TensorFlow runtime.\n",
      "\n",
      "See https://www.tensorflow.org/install/errors\n",
      "\n",
      "for some common reasons and solutions.  Include the entire stack trace\n",
      "above this error message when asking for help.\n"
     ]
    },
    {
     "ename": "NameError",
     "evalue": "name 'model' is not defined",
     "output_type": "error",
     "traceback": [
      "\u001b[1;31m---------------------------------------------------------------------------\u001b[0m"
     ]
    }
   ],
   "source": [
    "print(model.predict([10.0]))"
   ]
  },
  {
   "cell_type": "code",
   "execution_count": 4,
   "metadata": {},
   "outputs": [
    {
     "name": "stderr",
     "output_type": "stream",
     "text": [
      "ERROR:root:Internal Python error in the inspect module.\n",
      "Below is the traceback from this internal error.\n",
      "\n"
     ]
    },
    {
     "name": "stdout",
     "output_type": "stream",
     "text": [
      "Traceback (most recent call last):\n",
      "  File \"C:\\Anaconda\\lib\\site-packages\\IPython\\core\\interactiveshell.py\", line 3325, in run_code\n",
      "    exec(code_obj, self.user_global_ns, self.user_ns)\n",
      "  File \"<ipython-input-4-e543253bc1d3>\", line 4, in <module>\n",
      "    model.save(saved_model_path)\n",
      "NameError: name 'model' is not defined\n",
      "\n",
      "During handling of the above exception, another exception occurred:\n",
      "\n",
      "Traceback (most recent call last):\n",
      "  File \"C:\\Anaconda\\lib\\site-packages\\IPython\\core\\interactiveshell.py\", line 2039, in showtraceback\n",
      "    stb = value._render_traceback_()\n",
      "AttributeError: 'NameError' object has no attribute '_render_traceback_'\n",
      "\n",
      "During handling of the above exception, another exception occurred:\n",
      "\n",
      "Traceback (most recent call last):\n",
      "  File \"C:\\Users\\aravi\\AppData\\Roaming\\Python\\Python37\\site-packages\\tensorflow_core\\python\\pywrap_tensorflow.py\", line 58, in <module>\n",
      "    from tensorflow.python.pywrap_tensorflow_internal import *\n",
      "  File \"C:\\Users\\aravi\\AppData\\Roaming\\Python\\Python37\\site-packages\\tensorflow_core\\python\\pywrap_tensorflow_internal.py\", line 28, in <module>\n",
      "    _pywrap_tensorflow_internal = swig_import_helper()\n",
      "  File \"C:\\Users\\aravi\\AppData\\Roaming\\Python\\Python37\\site-packages\\tensorflow_core\\python\\pywrap_tensorflow_internal.py\", line 24, in swig_import_helper\n",
      "    _mod = imp.load_module('_pywrap_tensorflow_internal', fp, pathname, description)\n",
      "  File \"C:\\Anaconda\\lib\\imp.py\", line 242, in load_module\n",
      "    return load_dynamic(name, filename, file)\n",
      "  File \"C:\\Anaconda\\lib\\imp.py\", line 342, in load_dynamic\n",
      "    return _load(spec)\n",
      "ImportError: DLL load failed: The specified module could not be found.\n",
      "\n",
      "During handling of the above exception, another exception occurred:\n",
      "\n",
      "Traceback (most recent call last):\n",
      "  File \"C:\\Anaconda\\lib\\site-packages\\IPython\\core\\ultratb.py\", line 1101, in get_records\n",
      "    return _fixed_getinnerframes(etb, number_of_lines_of_context, tb_offset)\n",
      "  File \"C:\\Anaconda\\lib\\site-packages\\IPython\\core\\ultratb.py\", line 319, in wrapped\n",
      "    return f(*args, **kwargs)\n",
      "  File \"C:\\Anaconda\\lib\\site-packages\\IPython\\core\\ultratb.py\", line 353, in _fixed_getinnerframes\n",
      "    records = fix_frame_records_filenames(inspect.getinnerframes(etb, context))\n",
      "  File \"C:\\Anaconda\\lib\\inspect.py\", line 1502, in getinnerframes\n",
      "    frameinfo = (tb.tb_frame,) + getframeinfo(tb, context)\n",
      "  File \"C:\\Anaconda\\lib\\inspect.py\", line 1460, in getframeinfo\n",
      "    filename = getsourcefile(frame) or getfile(frame)\n",
      "  File \"C:\\Anaconda\\lib\\inspect.py\", line 696, in getsourcefile\n",
      "    if getattr(getmodule(object, filename), '__loader__', None) is not None:\n",
      "  File \"C:\\Anaconda\\lib\\inspect.py\", line 733, in getmodule\n",
      "    if ismodule(module) and hasattr(module, '__file__'):\n",
      "  File \"C:\\Users\\aravi\\AppData\\Roaming\\Python\\Python37\\site-packages\\tensorflow\\__init__.py\", line 50, in __getattr__\n",
      "    module = self._load()\n",
      "  File \"C:\\Users\\aravi\\AppData\\Roaming\\Python\\Python37\\site-packages\\tensorflow\\__init__.py\", line 44, in _load\n",
      "    module = _importlib.import_module(self.__name__)\n",
      "  File \"C:\\Anaconda\\lib\\importlib\\__init__.py\", line 127, in import_module\n",
      "    return _bootstrap._gcd_import(name[level:], package, level)\n",
      "  File \"<frozen importlib._bootstrap>\", line 1006, in _gcd_import\n",
      "  File \"<frozen importlib._bootstrap>\", line 983, in _find_and_load\n",
      "  File \"<frozen importlib._bootstrap>\", line 953, in _find_and_load_unlocked\n",
      "  File \"<frozen importlib._bootstrap>\", line 219, in _call_with_frames_removed\n",
      "  File \"<frozen importlib._bootstrap>\", line 1006, in _gcd_import\n",
      "  File \"<frozen importlib._bootstrap>\", line 983, in _find_and_load\n",
      "  File \"<frozen importlib._bootstrap>\", line 967, in _find_and_load_unlocked\n",
      "  File \"<frozen importlib._bootstrap>\", line 677, in _load_unlocked\n",
      "  File \"<frozen importlib._bootstrap_external>\", line 728, in exec_module\n",
      "  File \"<frozen importlib._bootstrap>\", line 219, in _call_with_frames_removed\n",
      "  File \"C:\\Users\\aravi\\AppData\\Roaming\\Python\\Python37\\site-packages\\tensorflow_core\\__init__.py\", line 42, in <module>\n",
      "    from . _api.v2 import audio\n",
      "  File \"C:\\Users\\aravi\\AppData\\Roaming\\Python\\Python37\\site-packages\\tensorflow_core\\_api\\v2\\audio\\__init__.py\", line 10, in <module>\n",
      "    from tensorflow.python.ops.gen_audio_ops import decode_wav\n",
      "  File \"C:\\Users\\aravi\\AppData\\Roaming\\Python\\Python37\\site-packages\\tensorflow_core\\python\\ops\\gen_audio_ops.py\", line 8, in <module>\n",
      "    from tensorflow.python import pywrap_tensorflow as _pywrap_tensorflow\n",
      "  File \"C:\\Users\\aravi\\AppData\\Roaming\\Python\\Python37\\site-packages\\tensorflow\\__init__.py\", line 50, in __getattr__\n",
      "    module = self._load()\n",
      "  File \"C:\\Users\\aravi\\AppData\\Roaming\\Python\\Python37\\site-packages\\tensorflow\\__init__.py\", line 44, in _load\n",
      "    module = _importlib.import_module(self.__name__)\n",
      "  File \"C:\\Anaconda\\lib\\importlib\\__init__.py\", line 127, in import_module\n",
      "    return _bootstrap._gcd_import(name[level:], package, level)\n",
      "  File \"C:\\Users\\aravi\\AppData\\Roaming\\Python\\Python37\\site-packages\\tensorflow_core\\python\\__init__.py\", line 49, in <module>\n",
      "    from tensorflow.python import pywrap_tensorflow\n",
      "  File \"C:\\Users\\aravi\\AppData\\Roaming\\Python\\Python37\\site-packages\\tensorflow_core\\python\\pywrap_tensorflow.py\", line 74, in <module>\n",
      "    raise ImportError(msg)\n",
      "ImportError: Traceback (most recent call last):\n",
      "  File \"C:\\Anaconda\\lib\\site-packages\\IPython\\core\\interactiveshell.py\", line 3325, in run_code\n",
      "    exec(code_obj, self.user_global_ns, self.user_ns)\n",
      "  File \"<ipython-input-4-e543253bc1d3>\", line 4, in <module>\n",
      "    model.save(saved_model_path)\n",
      "NameError: name 'model' is not defined\n",
      "\n",
      "During handling of the above exception, another exception occurred:\n",
      "\n",
      "Traceback (most recent call last):\n",
      "  File \"C:\\Anaconda\\lib\\site-packages\\IPython\\core\\interactiveshell.py\", line 2039, in showtraceback\n",
      "    stb = value._render_traceback_()\n",
      "AttributeError: 'NameError' object has no attribute '_render_traceback_'\n",
      "\n",
      "During handling of the above exception, another exception occurred:\n",
      "\n",
      "Traceback (most recent call last):\n",
      "  File \"C:\\Users\\aravi\\AppData\\Roaming\\Python\\Python37\\site-packages\\tensorflow_core\\python\\pywrap_tensorflow.py\", line 58, in <module>\n",
      "    from tensorflow.python.pywrap_tensorflow_internal import *\n",
      "  File \"C:\\Users\\aravi\\AppData\\Roaming\\Python\\Python37\\site-packages\\tensorflow_core\\python\\pywrap_tensorflow_internal.py\", line 28, in <module>\n",
      "    _pywrap_tensorflow_internal = swig_import_helper()\n",
      "  File \"C:\\Users\\aravi\\AppData\\Roaming\\Python\\Python37\\site-packages\\tensorflow_core\\python\\pywrap_tensorflow_internal.py\", line 24, in swig_import_helper\n",
      "    _mod = imp.load_module('_pywrap_tensorflow_internal', fp, pathname, description)\n",
      "  File \"C:\\Anaconda\\lib\\imp.py\", line 242, in load_module\n",
      "    return load_dynamic(name, filename, file)\n",
      "  File \"C:\\Anaconda\\lib\\imp.py\", line 342, in load_dynamic\n",
      "    return _load(spec)\n",
      "ImportError: DLL load failed: The specified module could not be found.\n",
      "\n",
      "\n",
      "Failed to load the native TensorFlow runtime.\n",
      "\n",
      "See https://www.tensorflow.org/install/errors\n",
      "\n",
      "for some common reasons and solutions.  Include the entire stack trace\n",
      "above this error message when asking for help.\n"
     ]
    },
    {
     "ename": "NameError",
     "evalue": "name 'model' is not defined",
     "output_type": "error",
     "traceback": [
      "\u001b[1;31m---------------------------------------------------------------------------\u001b[0m"
     ]
    }
   ],
   "source": [
    "import time\n",
    "saved_model_path = \"./{}.h5\".format(int(time.time()))\n",
    "\n",
    "model.save(saved_model_path)"
   ]
  },
  {
   "cell_type": "code",
   "execution_count": 5,
   "metadata": {},
   "outputs": [
    {
     "name": "stderr",
     "output_type": "stream",
     "text": [
      "'tensorflowjs_converter' is not recognized as an internal or external command,\n",
      "operable program or batch file.\n"
     ]
    }
   ],
   "source": [
    "!tensorflowjs_converter --input_format=keras {saved_model_path} ./"
   ]
  },
  {
   "cell_type": "code",
   "execution_count": null,
   "metadata": {},
   "outputs": [],
   "source": []
  }
 ],
 "metadata": {
  "accelerator": "GPU",
  "colab": {
   "collapsed_sections": [],
   "name": "Linear-to-JavaScript.ipynb",
   "provenance": [
    {
     "file_id": "1Aa_6zgDr53IyYdkyubWPvCJYTGzo7Ttr",
     "timestamp": 1554494369207
    }
   ],
   "version": "0.3.2"
  },
  "kernelspec": {
   "display_name": "Python 3",
   "language": "python",
   "name": "python3"
  },
  "language_info": {
   "codemirror_mode": {
    "name": "ipython",
    "version": 3
   },
   "file_extension": ".py",
   "mimetype": "text/x-python",
   "name": "python",
   "nbconvert_exporter": "python",
   "pygments_lexer": "ipython3",
   "version": "3.7.3"
  }
 },
 "nbformat": 4,
 "nbformat_minor": 1
}
